<?xml version="1.0"?>
<robot name="ball_follower_robot">

  <!-- Base Link -->
  <link name="base_link">
    <inertial>
      <mass value="1.0" />
      <origin xyz="0 0 0" />
      <inertia ixx="0.1" ixy="0.0" ixz="0.0" iyy="0.1" iyz="0.0" izz="0.1" />
    </inertial>
    <visual>
      <geometry>
        <box size="0.5 0.3 0.1"/>
      </geometry>
      <material name="blue">
        <color rgba="0 0 1 1"/>
      </material>
    </visual>
    <collision>
      <geometry>
        <box size="0.5 0.3 0.1"/>
      </geometry>
    </collision>
  </link>

  <!-- Left Wheel -->
  <link name="left_wheel">
    <visual>
      <geometry>
        <cylinder radius="0.1" length="0.05"/>
      </geometry>
      <material name="black">
        <color rgba="0 0 0 1"/>
      </material>
    </visual>
    <collision>
      <geometry>
        <cylinder radius="0.1" length="0.05"/>
      </geometry>
    </collision>
  </link>

  <!-- Right Wheel -->
  <link name="right_wheel">
    <visual>
      <geometry>
        <cylinder radius="0.1" length="0.05"/>
      </geometry>
      <material name="black">
        <color rgba="0 0 0 1"/>
      </material>
    </visual>
    <collision>
      <geometry>
        <cylinder radius="0.1" length="0.05"/>
      </geometry>
    </collision>
  </link>

  <!-- Caster Wheel -->
  <link name="caster_wheel">
    <visual>
      <geometry>
        <sphere radius="0.05"/>
      </geometry>
      <material name="black">
        <color rgba="0 0 0 1"/>
      </material>
    </visual>
    <collision>
      <geometry>
        <sphere radius="0.05"/>
      </geometry>
    </collision>
  </link>

  <!-- Joints -->
  <!-- Left Wheel Joint -->
  <joint name="left_wheel_joint" type="continuous">
    <parent link="base_link"/>
    <child link="left_wheel"/>
    <origin xyz="-0.25 0.15 0.05" rpy="0 1.5708 0"/>
    <axis xyz="0 1 0"/>
  </joint>

  <!-- Right Wheel Joint -->
  <joint name="right_wheel_joint" type="continuous">
    <parent link="base_link"/>
    <child link="right_wheel"/>
    <origin xyz="-0.25 -0.15 0.05" rpy="0 1.5708 0"/>
    <axis xyz="0 1 0"/>
  </joint>

  <!-- Caster Wheel Joint -->
  <joint name="caster_wheel_joint" type="fixed">
    <parent link="base_link"/>
    <child link="caster_wheel"/>
    <origin xyz="0.25 0 0.05" rpy="0 0 0"/>
  </joint>

  <!-- Inertial Properties -->
  <inertial>
    <mass value="0.1" />
    <origin xyz="0 0 0" />
    <inertia ixx="0.1" iyy="0.1" izz="0.1" />
  </inertial>

</robot>
